Workbook

Sheet Assumptions
A1: Lark — Business Model Assumptions
A2: Blue cells are inputs — change them to run scenarios. Black = formulas. All currency in EUR.
A3: GENERAL
A4: Currency | B4: EUR
A5: Mature MAU per city (steady state) | B5: 5000 | C5: Monthly active users a city settles at
A6: MAU ramp to maturity (months) | B6: 18 | C6: Linear ramp from launch to steady state
A7: Mature advertisers per city | B7: 25 | C7: Paying sponsored listings at maturity
A8: Advertiser ramp (months) | B8: 12 | C8: Sales ramp per city
A9: Listing price / advertiser / month | B9: 59 | C9: Flat sponsored-listing fee
A10: P&L scenario (1=HERE, 2=Hybrid, 3=Google) | B10: 2 | C10: Which API strategy feeds the P&L
A11: Include CPM ads? (1=yes, 0=no) | B11: 0 | C11: Generic banner/native ad revenue toggle
A13: CITY LAUNCH MONTH (1-36)
A14: City 1 (e.g. Munich) | B14: 1
A15: City 2 | B15: 9
A16: City 3 | B16: 18
A17: City 4 | B17: 27
A19: ENGAGEMENT — per MAU per month
A20: Sessions | B20: 6
A21: Map loads | B21: 8 | C21: Map tile / dynamic map loads
A22: Place searches (autocomplete) | B22: 5 | C22: Most expensive Google SKU
A23: Place details + photos | B23: 3 | C23: Fixes the bad/celebrity-image problem
A24: Geocoding lookups | B24: 2
A25: Routing calls | B25: 6 | C25: Recommend-flow travel-time batch
A26: Ad impressions | B26: 12 | C26: Discover-feed views (for CPM option)
A28: MONETISATION
A29: Affiliate booking rate (% of MAU / mo) | B29: 0.03 | C29: Share who complete a bookable activity
A30: Avg booking value | B30: 45 | C30: Per booking (tickets/tours)
A31: Affiliate commission % | B31: 0.08 | C31: GetYourGuide / Viator ~8%
A32: Subscription conversion % | B32: 0.03 | C32: Free users who upgrade
A33: Subscription price / month | B33: 3.49 | C33: Lark Premium
A34: CPM rate (per 1,000 impressions) | B34: 8 | C34: Germany Tier-2 native CPM
A36: API PRICING — per 1,000 calls (USD≈EUR 1:1 assumed)
A37: SKU | B37: Google | C37: Source: Google Maps Platform pricing 2026
A38: Map load (Dynamic Maps) | B38: 7
A39: Place search (Autocomplete) | B39: 17
A40: Place details + photos | B40: 17
A41: Geocoding | B41: 5
A42: Routing (Routes / Directions) | B42: 5
A43: HERE — blended price (any call) | B43: 0.8 | C43: Current provider; ~30k free/mo then low cost
A45: FREE TIERS — calls / month
...

Sheet Monthly Model
A1: Month | B1: Period | C1: Cities live | D1: Total MAU | E1: Advertisers | F1: Sponsored | G1: Affiliate | H1: Subscription | I1: CPM ads | J1: Total revenue | K1: API HERE-only | L1: API Hybrid | M1: API Google | N1: API selected | O1: Infra | P1: Opex | Q1: Total cost | R1: Net (month) | S1: Cumulative net | U1: C1 MAU | V1: C2 MAU | W1: C3 MAU | X1: C4 MAU | Y1: C1 adv | Z1: C2 adv | AA1: C3 adv | AB1: C4 adv | AC1: map | AD1: search | AE1: details | AF1: geo | AG1: route | AH1: BE-month | AI1: CumBE
A2: 1 | B2: Jun 2026 | C2: =SUMPRODUCT(--(Assumptions!$B$14:$B$17<=$A2)) -> 1 | D2: =SUM(U2:X2) -> 277.77778 | E2: =SUM(Y2:AB2) -> 2.0833333 | F2: =E2*Assumptions!$B$9 -> 122.91667 | G2: =D2*Assumptions!$B$29*Assumptions!$B$30*Assumptions!$B$31 -> 30 | H2: =D2*Assumptions!$B$32*Assumptions!$B$33 -> 29.083333 | I2: =D2*Assumptions!$B$26*Assumptions!$B$34/1000*Assumptions!$B$11 -> 0 | J2: =SUM(F2:I2) -> 182 | K2: =MAX(0,(AC2+AD2+AE2+AF2+AG2)-Assumptions!$B$47)/1000*Assumptions!$B$43 -> 0 | L2: =MAX(0,AD2-Assumptions!$B$46)/1000*Assumptions!$B$39+MAX(0,AE2-Assumptions!$B$46)/1000*Assumptions!$B$40+MAX(0,(AC2+AF2+AG2)-Assumptions!$B$47)/1000*Assumptions!$B$43 -> 0 | M2: =MAX(0,AC2-Assumptions!$B$46)/1000*Assumptions!$B$38+MAX(0,AD2-Assumptions!$B$46)/1000*Assumptions!$B$39+MAX(0,AE2-Assumptions!$B$46)/1000*Assumptions!$B$40+MAX(0,AF2-Assumptions!$B$46)/1000*Assumptions!$B$41+MAX(0,AG2-Assumptions!$B$46)/1000*Assumptions!$B$42 -> 0 | N2: =CHOOSE(Assumptions!$B$10,K2,L2,M2) -> 0 | O2: =IF(D2>Assumptions!$B$52,Assumptions!$B$51,Assumptions!$B$50) -> 0 | P2: =Assumptions!$B$53 -> 200 | Q2: =N2+O2+P2 -> 200 | R2: =J2-Q2 -> -18 | S2: =R2 -> -18 | U2: =IF($A2>=Assumptions!$B$14,MIN(Assumptions!$B$5,Assumptions!$B$5*($A2-Assumptions!$B$14+1)/Assumptions!$B$6),0) -> 277.77778 | V2: =IF($A2>=Assumptions!$B$15,MIN(Assumptions!$B$5,Assumptions!$B$5*($A2-Assumptions!$B$15+1)/Assumptions!$B$6),0) -> 0 | W2: =IF($A2>=Assumptions!$B$16,MIN(Assumptions!$B$5,Assumptions!$B$5*($A2-Assumptions!$B$16+1)/Assumptions!$B$6),0) -> 0 | X2: =IF($A2>=Assumptions!$B$17,MIN(Assumptions!$B$5,Assumptions!$B$5*($A2-Assumptions!$B$17+1)/Assumptions!$B$6),0) -> 0 | Y2: =IF($A2>=Assumptions!$B$14,Assumptions!$B$7*MIN(1,($A2-Assumptions!$B$14+1)/Assumptions!$B$8),0) -> 2.0833333 | Z2: =IF($A2>=Assumptions!$B$15,Assumptions!$B$7*MIN(1,($A2-Assumptions!$B$15+1)/Assumptions!$B$8),0) -> 0 | AA2: =IF($A2>=Assumptions!$B$16,Assumptions!$B$7*MIN(1,($A2-Assumptions!$B$16+1)/Assumptions!$B$8),0) -> 0 | AB2: =IF($A2>=Assumptions!$B$17,Assumptions!$B$7*MIN(1,($A2-Assumptions!$B$17+1)/Assumptions!$B$8),0) -> 0 | AC2: =D2*Assumptions!$B$21 -> 2222.2222 | AD2: =D2*Assumptions!$B$22 -> 1388.8889 | AE2: =D2*Assumptions!$B$23 -> 833.33333 | AF2: =D2*Assumptions!$B$24 -> 555.55556 | AG2: =D2*Assumptions!$B$25 -> 1666.6667 | AH2: =IF(R2>=0,A2,0) -> 0 | AI2: =IF(S2>=0,A2,0) -> 0
A3: 2 | B3: Jul 2026 | C3: =SUMPRODUCT(--(Assumptions!$B$14:$B$17<=$A3)) -> 1 | D3: =SUM(U3:X3) -> 555.55556 | E3: =SUM(Y3:AB3) -> 4.1666667 | F3: =E3*Assumptions!$B$9 -> 245.83333 | G3: =D3*Assumptions!$B$29*Assumptions!$B$30*Assumptions!$B$31 -> 60 | H3: =D3*Assumptions!$B$32*Assumptions!$B$33 -> 58.166667 | I3: =D3*Assumptions!$B$26*Assumptions!$B$34/1000*Assumptions!$B$11 -> 0 | J3: =SUM(F3:I3) -> 364 | K3: =MAX(0,(AC3+AD3+AE3+AF3+AG3)-Assumptions!$B$47)/1000*Assumptions!$B$43 -> 0 | L3: =MAX(0,AD3-Assumptions!$B$46)/1000*Assumptions!$B$39+MAX(0,AE3-Assumptions!$B$46)/1000*Assumptions!$B$40+MAX(0,(AC3+AF3+AG3)-Assumptions!$B$47)/1000*Assumptions!$B$43 -> 0 | M3: =MAX(0,AC3-Assumptions!$B$46)/1000*Assumptions!$B$38+MAX(0,AD3-Assumptions!$B$46)/1000*Assumptions!$B$39+MAX(0,AE3-Assumptions!$B$46)/1000*Assumptions!$B$40+MAX(0,AF3-Assumptions!$B$46)/1000*Assumptions!$B$41+MAX(0,AG3-Assumptions!$B$46)/1000*Assumptions!$B$42 -> 0 | N3: =CHOOSE(Assumptions!$B$10,K3,L3,M3) -> 0 | O3: =IF(D3>Assumptions!$B$52,Assumptions!$B$51,Assumptions!$B$50) -> 0 | P3: =Assumptions!$B$53 -> 200 | Q3: =N3+O3+P3 -> 200 | R3: =J3-Q3 -> 164 | S3: =S2+R3 -> 146 | U3: =IF($A3>=Assumptions!$B$14,MIN(Assumptions!$B$5,Assumptions!$B$5*($A3-Assumptions!$B$14+1)/Assumptions!$B$6),0) -> 555.55556 | V3: =IF($A3>=Assumptions!$B$15,MIN(Assumptions!$B$5,Assumptions!$B$5*($A3-Assumptions!$B$15+1)/Assumptions!$B$6),0) -> 0 | W3: =IF($A3>=Assumptions!$B$16,MIN(Assumptions!$B$5,Assumptions!$B$5*($A3-Assumptions!$B$16+1)/Assumptions!$B$6),0) -> 0 | X3: =IF($A3>=Assumptions!$B$17,MIN(Assumptions!$B$5,Assumptions!$B$5*($A3-Assumptions!$B$17+1)/Assumptions!$B$6),0) -> 0 | Y3: =IF($A3>=Assumptions!$B$14,Assumptions!$B$7*MIN(1,($A3-Assumptions!$B$14+1)/Assumptions!$B$8),0) -> 4.1666667 | Z3: =IF($A3>=Assumptions!$B$15,Assumptions!$B$7*MIN(1,($A3-Assumptions!$B$15+1)/Assumptions!$B$8),0) -> 0 | AA3: =IF($A3>=Assumptions!$B$16,Assumptions!$B$7*MIN(1,($A3-Assumptions!$B$16+1)/Assumptions!$B$8),0) -> 0 | AB3: =IF($A3>=Assumptions!$B$17,Assumptions!$B$7*MIN(1,($A3-Assumptions!$B$17+1)/Assumptions!$B$8),0) -> 0 | AC3: =D3*Assumptions!$B$21 -> 4444.4444 | AD3: =D3*Assumptions!$B$22 -> 2777.7778 | AE3: =D3*Assumptions!$B$23 -> 1666.6667 | AF3: =D3*Assumptions!$B$24 -> 1111.1111 | AG3: =D3*Assumptions!$B$25 -> 3333.3333 | AH3: =IF(AND(R3>=0,R2<0),A3,0) -> 2 | AI3: =IF(AND(S3>=0,S2<0),A3,0) -> 2
A4: 3 | B4: Aug 2026 | C4: =SUMPRODUCT(--(Assumptions!$B$14:$B$17<=$A4)) -> 1 | D4: =SUM(U4:X4) -> 833.33333 | E4: =SUM(Y4:AB4) -> 6.25 | F4: =E4*Assumptions!$B$9 -> 368.75 | G4: =D4*Assumptions!$B$29*Assumptions!$B$30*Assumptions!$B$31 -> 90 | H4: =D4*Assumptions!$B$32*Assumptions!$B$33 -> 87.25 | I4: =D4*Assumptions!$B$26*Assumptions!$B$34/1000*Assumptions!$B$11 -> 0 | J4: =SUM(F4:I4) -> 546 | K4: =MAX(0,(AC4+AD4+AE4+AF4+AG4)-Assumptions!$B$47)/1000*Assumptions!$B$43 -> 0 | L4: =MAX(0,AD4-Assumptions!$B$46)/1000*Assumptions!$B$39+MAX(0,AE4-Assumptions!$B$46)/1000*Assumptions!$B$40+MAX(0,(AC4+AF4+AG4)-Assumptions!$B$47)/1000*Assumptions!$B$43 -> 0 | M4: =MAX(0,AC4-Assumptions!$B$46)/1000*Assumptions!$B$38+MAX(0,AD4-Assumptions!$B$46)/1000*Assumptions!$B$39+MAX(0,AE4-Assumptions!$B$46)/1000*Assumptions!$B$40+MAX(0,AF4-Assumptions!$B$46)/1000*Assumptions!$B$41+MAX(0,AG4-Assumptions!$B$46)/1000*Assumptions!$B$42 -> 0 | N4: =CHOOSE(Assumptions!$B$10,K4,L4,M4) -> 0 | O4: =IF(D4>Assumptions!$B$52,Assumptions!$B$51,Assumptions!$B$50) -> 0 | P4: =Assumptions!$B$53 -> 200 | Q4: =N4+O4+P4 -> 200 | R4: =J4-Q4 -> 346 | S4: =S3+R4 -> 492 | U4: =IF($A4>=Assumptions!$B$14,MIN(Assumptions!$B$5,Assumptions!$B$5*($A4-Assumptions!$B$14+1)/Assumptions!$B$6),0) -> 833.33333 | V4: =IF($A4>=Assumptions!$B$15,MIN(Assumptions!$B$5,Assumptions!$B$5*($A4-Assumptions!$B$15+1)/Assumptions!$B$6),0) -> 0 | W4: =IF($A4>=Assumptions!$B$16,MIN(Assumptions!$B$5,Assumptions!$B$5*($A4-Assumptions!$B$16+1)/Assumptions!$B$6),0) -> 0 | X4: =IF($A4>=Assumptions!$B$17,MIN(Assumptions!$B$5,Assumptions!$B$5*($A4-Assumptions!$B$17+1)/Assumptions!$B$6),0) -> 0 | Y4: =IF($A4>=Assumptions!$B$14,Assumptions!$B$7*MIN(1,($A4-Assumptions!$B$14+1)/Assumptions!$B$8),0) -> 6.25 | Z4: =IF($A4>=Assumptions!$B$15,Assumptions!$B$7*MIN(1,($A4-Assumptions!$B$15+1)/Assumptions!$B$8),0) -> 0 | AA4: =IF($A4>=Assumptions!$B$16,Assumptions!$B$7*MIN(1,($A4-Assumptions!$B$16+1)/Assumptions!$B$8),0) -> 0 | AB4: =IF($A4>=Assumptions!$B$17,Assumptions!$B$7*MIN(1,($A4-Assumptions!$B$17+1)/Assumptions!$B$8),0) -> 0 | AC4: =D4*Assumptions!$B$21 -> 6666.6667 | AD4: =D4*Assumptions!$B$22 -> 4166.6667 | AE4: =D4*Assumptions!$B$23 -> 2500 | AF4: =D4*Assumptions!$B$24 -> 1666.6667 | AG4: =D4*Assumptions!$B$25 -> 5000 | AH4: =IF(AND(R4>=0,R3<0),A4,0) -> 0 | AI4: =IF(AND(S4>=0,S3<0),A4,0) -> 0
A5: 4 | B5: Sep 2026 | C5: =SUMPRODUCT(--(Assumptions!$B$14:$B$17<=$A5)) -> 1 | D5: =SUM(U5:X5) -> 1111.1111 | E5: =SUM(Y5:AB5) -> 8.3333333 | F5: =E5*Assumptions!$B$9 -> 491.66667 | G5: =D5*Assumptions!$B$29*Assumptions!$B$30*Assumptions!$B$31 -> 120 | H5: =D5*Assumptions!$B$32*Assumptions!$B$33 -> 116.33333 | I5: =D5*Assumptions!$B$26*Assumptions!$B$34/1000*Assumptions!$B$11 -> 0 | J5: =SUM(F5:I5) -> 728 | K5: =MAX(0,(AC5+AD5+AE5+AF5+AG5)-Assumptions!$B$47)/1000*Assumptions!$B$43 -> 0 | L5: =MAX(0,AD5-Assumptions!$B$46)/1000*Assumptions!$B$39+MAX(0,AE5-Assumptions!$B$46)/1000*Assumptions!$B$40+MAX(0,(AC5+AF5+AG5)-Assumptions!$B$47)/1000*Assumptions!$B$43 -> 0 | M5: =MAX(0,AC5-Assumptions!$B$46)/1000*Assumptions!$B$38+MAX(0,AD5-Assumptions!$B$46)/1000*Assumptions!$B$39+MAX(0,AE5-Assumptions!$B$46)/1000*Assumptions!$B$40+MAX(0,AF5-Assumptions!$B$46)/1000*Assumptions!$B$41+MAX(0,AG5-Assumptions!$B$46)/1000*Assumptions!$B$42 -> 0 | N5: =CHOOSE(Assumptions!$B$10,K5,L5,M5) -> 0 | O5: =IF(D5>Assumptions!$B$52,Assumptions!$B$51,Assumptions!$B$50) -> 0 | P5: =Assumptions!$B$53 -> 200 | Q5: =N5+O5+P5 -> 200 | R5: =J5-Q5 -> 528 | S5: =S4+R5 -> 1020 | U5: =IF($A5>=Assumptions!$B$14,MIN(Assumptions!$B$5,Assumptions!$B$5*($A5-Assumptions!$B$14+1)/Assumptions!$B$6),0) -> 1111.1111 | V5: =IF($A5>=Assumptions!$B$15,MIN(Assumptions!$B$5,Assumptions!$B$5*($A5-Assumptions!$B$15+1)/Assumptions!$B$6),0) -> 0 | W5: =IF($A5>=Assumptions!$B$16,MIN(Assumptions!$B$5,Assumptions!$B$5*($A5-Assumptions!$B$16+1)/Assumptions!$B$6),0) -> 0 | X5: =IF($A5>=Assumptions!$B$17,MIN(Assumptions!$B$5,Assumptions!$B$5*($A5-Assumptions!$B$17+1)/Assumptions!$B$6),0) -> 0 | Y5: =IF($A5>=Assumptions!$B$14,Assumptions!$B$7*MIN(1,($A5-Assumptions!$B$14+1)/Assumptions!$B$8),0) -> 8.3333333 | Z5: =IF($A5>=Assumptions!$B$15,Assumptions!$B$7*MIN(1,($A5-Assumptions!$B$15+1)/Assumptions!$B$8),0) -> 0 | AA5: =IF($A5>=Assumptions!$B$16,Assumptions!$B$7*MIN(1,($A5-Assumptions!$B$16+1)/Assumptions!$B$8),0) -> 0 | AB5: =IF($A5>=Assumptions!$B$17,Assumptions!$B$7*MIN(1,($A5-Assumptions!$B$17+1)/Assumptions!$B$8),0) -> 0 | AC5: =D5*Assumptions!$B$21 -> 8888.8889 | AD5: =D5*Assumptions!$B$22 -> 5555.5556 | AE5: =D5*Assumptions!$B$23 -> 3333.3333 | AF5: =D5*Assumptions!$B$24 -> 2222.2222 | AG5: =D5*Assumptions!$B$25 -> 6666.6667 | AH5: =IF(AND(R5>=0,R4<0),A5,0) -> 0 | AI5: =IF(AND(S5>=0,S4<0),A5,0) -> 0
A6: 5 | B6: Oct 2026 | C6: =SUMPRODUCT(--(Assumptions!$B$14:$B$17<=$A6)) -> 1 | D6: =SUM(U6:X6) -> 1388.8889 | E6: =SUM(Y6:AB6) -> 10.416667 | F6: =E6*Assumptions!$B$9 -> 614.58333 | G6: =D6*Assumptions!$B$29*Assumptions!$B$30*Assumptions!$B$31 -> 150 | H6: =D6*Assumptions!$B$32*Assumptions!$B$33 -> 145.41667 | I6: =D6*Assumptions!$B$26*Assumptions!$B$34/1000*Assumptions!$B$11 -> 0 | J6: =SUM(F6:I6) -> 910 | K6: =MAX(0,(AC6+AD6+AE6+AF6+AG6)-Assumptions!$B$47)/1000*Assumptions!$B$43 -> 2.6666667 | L6: =MAX(0,AD6-Assumptions!$B$46)/1000*Assumptions!$B$39+MAX(0,AE6-Assumptions!$B$46)/1000*Assumptions!$B$40+MAX(0,(AC6+AF6+AG6)-Assumptions!$B$47)/1000*Assumptions!$B$43 -> 0 | M6: =MAX(0,AC6-Assumptions!$B$46)/1000*Assumptions!$B$38+MAX(0,AD6-Assumptions!$B$46)/1000*Assumptions!$B$39+MAX(0,AE6-Assumptions!$B$46)/1000*Assumptions!$B$40+MAX(0,AF6-Assumptions!$B$46)/1000*Assumptions!$B$41+MAX(0,AG6-Assumptions!$B$46)/1000*Assumptions!$B$42 -> 7.7777778 | N6: =CHOOSE(Assumptions!$B$10,K6,L6,M6) -> 0 | O6: =IF(D6>Assumptions!$B$52,Assumptions!$B$51,Assumptions!$B$50) -> 0 | P6: =Assumptions!$B$53 -> 200 | Q6: =N6+O6+P6 -> 200 | R6: =J6-Q6 -> 710 | S6: =S5+R6 -> 1730 | U6: =IF($A6>=Assumptions!$B$14,MIN(Assumptions!$B$5,Assumptions!$B$5*($A6-Assumptions!$B$14+1)/Assumptions!$B$6),0) -> 1388.8889 | V6: =IF($A6>=Assumptions!$B$15,MIN(Assumptions!$B$5,Assumptions!$B$5*($A6-Assumptions!$B$15+1)/Assumptions!$B$6),0) -> 0 | W6: =IF($A6>=Assumptions!$B$16,MIN(Assumptions!$B$5,Assumptions!$B$5*($A6-Assumptions!$B$16+1)/Assumptions!$B$6),0) -> 0 | X6: =IF($A6>=Assumptions!$B$17,MIN(Assumptions!$B$5,Assumptions!$B$5*($A6-Assumptions!$B$17+1)/Assumptions!$B$6),0) -> 0 | Y6: =IF($A6>=Assumptions!$B$14,Assumptions!$B$7*MIN(1,($A6-Assumptions!$B$14+1)/Assumptions!$B$8),0) -> 10.416667 | Z6: =IF($A6>=Assumptions!$B$15,Assumptions!$B$7*MIN(1,($A6-Assumptions!$B$15+1)/Assumptions!$B$8),0) -> 0 | AA6: =IF($A6>=Assumptions!$B$16,Assumptions!$B$7*MIN(1,($A6-Assumptions!$B$16+1)/Assumptions!$B$8),0) -> 0 | AB6: =IF($A6>=Assumptions!$B$17,Assumptions!$B$7*MIN(1,($A6-Assumptions!$B$17+1)/Assumptions!$B$8),0) -> 0 | AC6: =D6*Assumptions!$B$21 -> 11111.111 | AD6: =D6*Assumptions!$B$22 -> 6944.4444 | AE6: =D6*Assumptions!$B$23 -> 4166.6667 | AF6: =D6*Assumptions!$B$24 -> 2777.7778 | AG6: =D6*Assumptions!$B$25 -> 8333.3333 | AH6: =IF(AND(R6>=0,R5<0),A6,0) -> 0 | AI6: =IF(AND(S6>=0,S5<0),A6,0) -> 0
A7: 6 | B7: Nov 2026 | C7: =SUMPRODUCT(--(Assumptions!$B$14:$B$17<=$A7)) -> 1 | D7: =SUM(U7:X7) -> 1666.6667 | E7: =SUM(Y7:AB7) -> 12.5 | F7: =E7*Assumptions!$B$9 -> 737.5 | G7: =D7*Assumptions!$B$29*Assumptions!$B$30*Assumptions!$B$31 -> 180 | H7: =D7*Assumptions!$B$32*Assumptions!$B$33 -> 174.5 | I7: =D7*Assumptions!$B$26*Assumptions!$B$34/1000*Assumptions!$B$11 -> 0 | J7: =SUM(F7:I7) -> 1092 | K7: =MAX(0,(AC7+AD7+AE7+AF7+AG7)-Assumptions!$B$47)/1000*Assumptions!$B$43 -> 8 | L7: =MAX(0,AD7-Assumptions!$B$46)/1000*Assumptions!$B$39+MAX(0,AE7-Assumptions!$B$46)/1000*Assumptions!$B$40+MAX(0,(AC7+AF7+AG7)-Assumptions!$B$47)/1000*Assumptions!$B$43 -> 0 | M7: =MAX(0,AC7-Assumptions!$B$46)/1000*Assumptions!$B$38+MAX(0,AD7-Assumptions!$B$46)/1000*Assumptions!$B$39+MAX(0,AE7-Assumptions!$B$46)/1000*Assumptions!$B$40+MAX(0,AF7-Assumptions!$B$46)/1000*Assumptions!$B$41+MAX(0,AG7-Assumptions!$B$46)/1000*Assumptions!$B$42 -> 23.333333 | N7: =CHOOSE(Assumptions!$B$10,K7,L7,M7) -> 0 | O7: =IF(D7>Assumptions!$B$52,Assumptions!$B$51,Assumptions!$B$50) -> 0 | P7: =Assumptions!$B$53 -> 200 | Q7: =N7+O7+P7 -> 200 | R7: =J7-Q7 -> 892 | S7: =S6+R7 -> 2622 | U7: =IF($A7>=Assumptions!$B$14,MIN(Assumptions!$B$5,Assumptions!$B$5*($A7-Assumptions!$B$14+1)/Assumptions!$B$6),0) -> 1666.6667 | V7: =IF($A7>=Assumptions!$B$15,MIN(Assumptions!$B$5,Assumptions!$B$5*($A7-Assumptions!$B$15+1)/Assumptions!$B$6),0) -> 0 | W7: =IF($A7>=Assumptions!$B$16,MIN(Assumptions!$B$5,Assumptions!$B$5*($A7-Assumptions!$B$16+1)/Assumptions!$B$6),0) -> 0 | X7: =IF($A7>=Assumptions!$B$17,MIN(Assumptions!$B$5,Assumptions!$B$5*($A7-Assumptions!$B$17+1)/Assumptions!$B$6),0) -> 0 | Y7: =IF($A7>=Assumptions!$B$14,Assumptions!$B$7*MIN(1,($A7-Assumptions!$B$14+1)/Assumptions!$B$8),0) -> 12.5 | Z7: =IF($A7>=Assumptions!$B$15,Assumptions!$B$7*MIN(1,($A7-Assumptions!$B$15+1)/Assumptions!$B$8),0) -> 0 | AA7: =IF($A7>=Assumptions!$B$16,Assumptions!$B$7*MIN(1,($A7-Assumptions!$B$16+1)/Assumptions!$B$8),0) -> 0 | AB7: =IF($A7>=Assumptions!$B$17,Assumptions!$B$7*MIN(1,($A7-Assumptions!$B$17+1)/Assumptions!$B$8),0) -> 0 | AC7: =D7*Assumptions!$B$21 -> 13333.333 | AD7: =D7*Assumptions!$B$22 -> 8333.3333 | AE7: =D7*Assumptions!$B$23 -> 5000 | AF7: =D7*Assumptions!$B$24 -> 3333.3333 | AG7: =D7*Assumptions!$B$25 -> 10000 | AH7: =IF(AND(R7>=0,R6<0),A7,0) -> 0 | AI7: =IF(AND(S7>=0,S6<0),A7,0) -> 0
A8: 7 | B8: Dec 2026 | C8: =SUMPRODUCT(--(Assumptions!$B$14:$B$17<=$A8)) -> 1 | D8: =SUM(U8:X8) -> 1944.4444 | E8: =SUM(Y8:AB8) -> 14.583333 | F8: =E8*Assumptions!$B$9 -> 860.41667 | G8: =D8*Assumptions!$B$29*Assumptions!$B$30*Assumptions!$B$31 -> 210 | H8: =D8*Assumptions!$B$32*Assumptions!$B$33 -> 203.58333 | I8: =D8*Assumptions!$B$26*Assumptions!$B$34/1000*Assumptions!$B$11 -> 0 | J8: =SUM(F8:I8) -> 1274 | K8: =MAX(0,(AC8+AD8+AE8+AF8+AG8)-Assumptions!$B$47)/1000*Assumptions!$B$43 -> 13.333333 | L8: =MAX(0,AD8-Assumptions!$B$46)/1000*Assumptions!$B$39+MAX(0,AE8-Assumptions!$B$46)/1000*Assumptions!$B$40+MAX(0,(AC8+AF8+AG8)-Assumptions!$B$47)/1000*Assumptions!$B$43 -> 0.88888889 | M8: =MAX(0,AC8-Assumptions!$B$46)/1000*Assumptions!$B$38+MAX(0,AD8-Assumptions!$B$46)/1000*Assumptions!$B$39+MAX(0,AE8-Assumptions!$B$46)/1000*Assumptions!$B$40+MAX(0,AF8-Assumptions!$B$46)/1000*Assumptions!$B$41+MAX(0,AG8-Assumptions!$B$46)/1000*Assumptions!$B$42 -> 47.222222 | N8: =CHOOSE(Assumptions!$B$10,K8,L8,M8) -> 0.88888889 | O8: =IF(D8>Assumptions!$B$52,Assumptions!$B$51,Assumptions!$B$50) -> 0 | P8: =Assumptions!$B$53 -> 200 | Q8: =N8+O8+P8 -> 200.88889 | R8: =J8-Q8 -> 1073.1111 | S8: =S7+R8 -> 3695.1111 | U8: =IF($A8>=Assumptions!$B$14,MIN(Assumptions!$B$5,Assumptions!$B$5*($A8-Assumptions!$B$14+1)/Assumptions!$B$6),0) -> 1944.4444 | V8: =IF($A8>=Assumptions!$B$15,MIN(Assumptions!$B$5,Assumptions!$B$5*($A8-Assumptions!$B$15+1)/Assumptions!$B$6),0) -> 0 | W8: =IF($A8>=Assumptions!$B$16,MIN(Assumptions!$B$5,Assumptions!$B$5*($A8-Assumptions!$B$16+1)/Assumptions!$B$6),0) -> 0 | X8: =IF($A8>=Assumptions!$B$17,MIN(Assumptions!$B$5,Assumptions!$B$5*($A8-Assumptions!$B$17+1)/Assumptions!$B$6),0) -> 0 | Y8: =IF($A8>=Assumptions!$B$14,Assumptions!$B$7*MIN(1,($A8-Assumptions!$B$14+1)/Assumptions!$B$8),0) -> 14.583333 | Z8: =IF($A8>=Assumptions!$B$15,Assumptions!$B$7*MIN(1,($A8-Assumptions!$B$15+1)/Assumptions!$B$8),0) -> 0 | AA8: =IF($A8>=Assumptions!$B$16,Assumptions!$B$7*MIN(1,($A8-Assumptions!$B$16+1)/Assumptions!$B$8),0) -> 0 | AB8: =IF($A8>=Assumptions!$B$17,Assumptions!$B$7*MIN(1,($A8-Assumptions!$B$17+1)/Assumptions!$B$8),0) -> 0 | AC8: =D8*Assumptions!$B$21 -> 15555.556 | AD8: =D8*Assumptions!$B$22 -> 9722.2222 | AE8: =D8*Assumptions!$B$23 -> 5833.3333 | AF8: =D8*Assumptions!$B$24 -> 3888.8889 | AG8: =D8*Assumptions!$B$25 -> 11666.667 | AH8: =IF(AND(R8>=0,R7<0),A8,0) -> 0 | AI8: =IF(AND(S8>=0,S7<0),A8,0) -> 0
A9: 8 | B9: Jan 2027 | C9: =SUMPRODUCT(--(Assumptions!$B$14:$B$17<=$A9)) -> 1 | D9: =SUM(U9:X9) -> 2222.2222 | E9: =SUM(Y9:AB9) -> 16.666667 | F9: =E9*Assumptions!$B$9 -> 983.33333 | G9: =D9*Assumptions!$B$29*Assumptions!$B$30*Assumptions!$B$31 -> 240 | H9: =D9*Assumptions!$B$32*Assumptions!$B$33 -> 232.66667 | I9: =D9*Assumptions!$B$26*Assumptions!$B$34/1000*Assumptions!$B$11 -> 0 | J9: =SUM(F9:I9) -> 1456 | K9: =MAX(0,(AC9+AD9+AE9+AF9+AG9)-Assumptions!$B$47)/1000*Assumptions!$B$43 -> 18.666667 | L9: =MAX(0,AD9-Assumptions!$B$46)/1000*Assumptions!$B$39+MAX(0,AE9-Assumptions!$B$46)/1000*Assumptions!$B$40+MAX(0,(AC9+AF9+AG9)-Assumptions!$B$47)/1000*Assumptions!$B$43 -> 23.333333 | M9: =MAX(0,AC9-Assumptions!$B$46)/1000*Assumptions!$B$38+MAX(0,AD9-Assumptions!$B$46)/1000*Assumptions!$B$39+MAX(0,AE9-Assumptions!$B$46)/1000*Assumptions!$B$40+MAX(0,AF9-Assumptions!$B$46)/1000*Assumptions!$B$41+MAX(0,AG9-Assumptions!$B$46)/1000*Assumptions!$B$42 -> 90 | N9: =CHOOSE(Assumptions!$B$10,K9,L9,M9) -> 23.333333 | O9: =IF(D9>Assumptions!$B$52,Assumptions!$B$51,Assumptions!$B$50) -> 0 | P9: =Assumptions!$B$53 -> 200 | Q9: =N9+O9+P9 -> 223.33333 | R9: =J9-Q9 -> 1232.6667 | S9: =S8+R9 -> 4927.7778 | U9: =IF($A9>=Assumptions!$B$14,MIN(Assumptions!$B$5,Assumptions!$B$5*($A9-Assumptions!$B$14+1)/Assumptions!$B$6),0) -> 2222.2222 | V9: =IF($A9>=Assumptions!$B$15,MIN(Assumptions!$B$5,Assumptions!$B$5*($A9-Assumptions!$B$15+1)/Assumptions!$B$6),0) -> 0 | W9: =IF($A9>=Assumptions!$B$16,MIN(Assumptions!$B$5,Assumptions!$B$5*($A9-Assumptions!$B$16+1)/Assumptions!$B$6),0) -> 0 | X9: =IF($A9>=Assumptions!$B$17,MIN(Assumptions!$B$5,Assumptions!$B$5*($A9-Assumptions!$B$17+1)/Assumptions!$B$6),0) -> 0 | Y9: =IF($A9>=Assumptions!$B$14,Assumptions!$B$7*MIN(1,($A9-Assumptions!$B$14+1)/Assumptions!$B$8),0) -> 16.666667 | Z9: =IF($A9>=Assumptions!$B$15,Assumptions!$B$7*MIN(1,($A9-Assumptions!$B$15+1)/Assumptions!$B$8),0) -> 0 | AA9: =IF($A9>=Assumptions!$B$16,Assumptions!$B$7*MIN(1,($A9-Assumptions!$B$16+1)/Assumptions!$B$8),0) -> 0 | AB9: =IF($A9>=Assumptions!$B$17,Assumptions!$B$7*MIN(1,($A9-Assumptions!$B$17+1)/Assumptions!$B$8),0) -> 0 | AC9: =D9*Assumptions!$B$21 -> 17777.778 | AD9: =D9*Assumptions!$B$22 -> 11111.111 | AE9: =D9*Assumptions!$B$23 -> 6666.6667 | AF9: =D9*Assumptions!$B$24 -> 4444.4444 | AG9: =D9*Assumptions!$B$25 -> 13333.333 | AH9: =IF(AND(R9>=0,R8<0),A9,0) -> 0 | AI9: =IF(AND(S9>=0,S8<0),A9,0) -> 0
A10: 9 | B10: Feb 2027 | C10: =SUMPRODUCT(--(Assumptions!$B$14:$B$17<=$A10)) -> 2 | D10: =SUM(U10:X10) -> 2777.7778 | E10: =SUM(Y10:AB10) -> 20.833333 | F10: =E10*Assumptions!$B$9 -> 1229.1667 | G10: =D10*Assumptions!$B$29*Assumptions!$B$30*Assumptions!$B$31 -> 300 | H10: =D10*Assumptions!$B$32*Assumptions!$B$33 -> 290.83333 | I10: =D10*Assumptions!$B$26*Assumptions!$B$34/1000*Assumptions!$B$11 -> 0 | J10: =SUM(F10:I10) -> 1820 | K10: =MAX(0,(AC10+AD10+AE10+AF10+AG10)-Assumptions!$B$47)/1000*Assumptions!$B$43 -> 29.333333 | L10: =MAX(0,AD10-Assumptions!$B$46)/1000*Assumptions!$B$39+MAX(0,AE10-Assumptions!$B$46)/1000*Assumptions!$B$40+MAX(0,(AC10+AF10+AG10)-Assumptions!$B$47)/1000*Assumptions!$B$43 -> 77.666667 | M10: =MAX(0,AC10-Assumptions!$B$46)/1000*Assumptions!$B$38+MAX(0,AD10-Assumptions!$B$46)/1000*Assumptions!$B$39+MAX(0,AE10-Assumptions!$B$46)/1000*Assumptions!$B$40+MAX(0,AF10-Assumptions!$B$46)/1000*Assumptions!$B$41+MAX(0,AG10-Assumptions!$B$46)/1000*Assumptions!$B$42 -> 185 | N10: =CHOOSE(Assumptions!$B$10,K10,L10,M10) -> 77.666667 | O10: =IF(D10>Assumptions!$B$52,Assumptions!$B$51,Assumptions!$B$50) -> 0 | P10: =Assumptions!$B$53 -> 200 | Q10: =N10+O10+P10 -> 277.66667 | R10: =J10-Q10 -> 1542.3333 | S10: =S9+R10 -> 6470.1111 | U10: =IF($A10>=Assumptions!$B$14,MIN(Assumptions!$B$5,Assumptions!$B$5*($A10-Assumptions!$B$14+1)/Assumptions!$B$6),0) -> 2500 | V10: =IF($A10>=Assumptions!$B$15,MIN(Assumptions!$B$5,Assumptions!$B$5*($A10-Assumptions!$B$15+1)/Assumptions!$B$6),0) -> 277.77778 | W10: =IF($A10>=Assumptions!$B$16,MIN(Assumptions!$B$5,Assumptions!$B$5*($A10-Assumptions!$B$16+1)/Assumptions!$B$6),0) -> 0 | X10: =IF($A10>=Assumptions!$B$17,MIN(Assumptions!$B$5,Assumptions!$B$5*($A10-Assumptions!$B$17+1)/Assumptions!$B$6),0) -> 0 | Y10: =IF($A10>=Assumptions!$B$14,Assumptions!$B$7*MIN(1,($A10-Assumptions!$B$14+1)/Assumptions!$B$8),0) -> 18.75 | Z10: =IF($A10>=Assumptions!$B$15,Assumptions!$B$7*MIN(1,($A10-Assumptions!$B$15+1)/Assumptions!$B$8),0) -> 2.0833333 | AA10: =IF($A10>=Assumptions!$B$16,Assumptions!$B$7*MIN(1,($A10-Assumptions!$B$16+1)/Assumptions!$B$8),0) -> 0 | AB10: =IF($A10>=Assumptions!$B$17,Assumptions!$B$7*MIN(1,($A10-Assumptions!$B$17+1)/Assumptions!$B$8),0) -> 0 | AC10: =D10*Assumptions!$B$21 -> 22222.222 | AD10: =D10*Assumptions!$B$22 -> 13888.889 | AE10: =D10*Assumptions!$B$23 -> 8333.3333 | AF10: =D10*Assumptions!$B$24 -> 5555.5556 | AG10: =D10*Assumptions!$B$25 -> 16666.667 | AH10: =IF(AND(R10>=0,R9<0),A10,0) -> 0 | AI10: =IF(AND(S10>=0,S9<0),A10,0) -> 0
A11: 10 | B11: Mar 2027 | C11: =SUMPRODUCT(--(Assumptions!$B$14:$B$17<=$A11)) -> 2 | D11: =SUM(U11:X11) -> 3333.3333 | E11: =SUM(Y11:AB11) -> 25 | F11: =E11*Assumptions!$B$9 -> 1475 | G11: =D11*Assumptions!$B$29*Assumptions!$B$30*Assumptions!$B$31 -> 360 | H11: =D11*Assumptions!$B$32*Assumptions!$B$33 -> 349 | I11: =D11*Assumptions!$B$26*Assumptions!$B$34/1000*Assumptions!$B$11 -> 0 | J11: =SUM(F11:I11) -> 2184 | K11: =MAX(0,(AC11+AD11+AE11+AF11+AG11)-Assumptions!$B$47)/1000*Assumptions!$B$43 -> 40 | L11: =MAX(0,AD11-Assumptions!$B$46)/1000*Assumptions!$B$39+MAX(0,AE11-Assumptions!$B$46)/1000*Assumptions!$B$40+MAX(0,(AC11+AF11+AG11)-Assumptions!$B$47)/1000*Assumptions!$B$43 -> 132 | M11: =MAX(0,AC11-Assumptions!$B$46)/1000*Assumptions!$B$38+MAX(0,AD11-Assumptions!$B$46)/1000*Assumptions!$B$39+MAX(0,AE11-Assumptions!$B$46)/1000*Assumptions!$B$40+MAX(0,AF11-Assumptions!$B$46)/1000*Assumptions!$B$41+MAX(0,AG11-Assumptions!$B$46)/1000*Assumptions!$B$42 -> 280 | N11: =CHOOSE(Assumptions!$B$10,K11,L11,M11) -> 132 | O11: =IF(D11>Assumptions!$B$52,Assumptions!$B$51,Assumptions!$B$50) -> 0 | P11: =Assumptions!$B$53 -> 200 | Q11: =N11+O11+P11 -> 332 | R11: =J11-Q11 -> 1852 | S11: =S10+R11 -> 8322.1111 | U11: =IF($A11>=Assumptions!$B$14,MIN(Assumptions!$B$5,Assumptions!$B$5*($A11-Assumptions!$B$14+1)/Assumptions!$B$6),0) -> 2777.7778 | V11: =IF($A11>=Assumptions!$B$15,MIN(Assumptions!$B$5,Assumptions!$B$5*($A11-Assumptions!$B$15+1)/Assumptions!$B$6),0) -> 555.55556 | W11: =IF($A11>=Assumptions!$B$16,MIN(Assumptions!$B$5,Assumptions!$B$5*($A11-Assumptions!$B$16+1)/Assumptions!$B$6),0) -> 0 | X11: =IF($A11>=Assumptions!$B$17,MIN(Assumptions!$B$5,Assumptions!$B$5*($A11-Assumptions!$B$17+1)/Assumptions!$B$6),0) -> 0 | Y11: =IF($A11>=Assumptions!$B$14,Assumptions!$B$7*MIN(1,($A11-Assumptions!$B$14+1)/Assumptions!$B$8),0) -> 20.833333 | Z11: =IF($A11>=Assumptions!$B$15,Assumptions!$B$7*MIN(1,($A11-Assumptions!$B$15+1)/Assumptions!$B$8),0) -> 4.1666667 | AA11: =IF($A11>=Assumptions!$B$16,Assumptions!$B$7*MIN(1,($A11-Assumptions!$B$16+1)/Assumptions!$B$8),0) -> 0 | AB11: =IF($A11>=Assumptions!$B$17,Assumptions!$B$7*MIN(1,($A11-Assumptions!$B$17+1)/Assumptions!$B$8),0) -> 0 | AC11: =D11*Assumptions!$B$21 -> 26666.667 | AD11: =D11*Assumptions!$B$22 -> 16666.667 | AE11: =D11*Assumptions!$B$23 -> 10000 | AF11: =D11*Assumptions!$B$24 -> 6666.6667 | AG11: =D11*Assumptions!$B$25 -> 20000 | AH11: =IF(AND(R11>=0,R10<0),A11,0) -> 0 | AI11: =IF(AND(S11>=0,S10<0),A11,0) -> 0
A12: 11 | B12: Apr 2027 | C12: =SUMPRODUCT(--(Assumptions!$B$14:$B$17<=$A12)) -> 2 | D12: =SUM(U12:X12) -> 3888.8889 | E12: =SUM(Y12:AB12) -> 29.166667 | F12: =E12*Assumptions!$B$9 -> 1720.8333 | G12: =D12*Assumptions!$B$29*Assumptions!$B$30*Assumptions!$B$31 -> 420 | H12: =D12*Assumptions!$B$32*Assumptions!$B$33 -> 407.16667 | I12: =D12*Assumptions!$B$26*Assumptions!$B$34/1000*Assumptions!$B$11 -> 0 | J12: =SUM(F12:I12) -> 2548 | K12: =MAX(0,(AC12+AD12+AE12+AF12+AG12)-Assumptions!$B$47)/1000*Assumptions!$B$43 -> 50.666667 | L12: =MAX(0,AD12-Assumptions!$B$46)/1000*Assumptions!$B$39+MAX(0,AE12-Assumptions!$B$46)/1000*Assumptions!$B$40+MAX(0,(AC12+AF12+AG12)-Assumptions!$B$47)/1000*Assumptions!$B$43 -> 214.66667 | M12: =MAX(0,AC12-Assumptions!$B$46)/1000*Assumptions!$B$38+MAX(0,AD12-Assumptions!$B$46)/1000*Assumptions!$B$39+MAX(0,AE12-Assumptions!$B$46)/1000*Assumptions!$B$40+MAX(0,AF12-Assumptions!$B$46)/1000*Assumptions!$B$41+MAX(0,AG12-Assumptions!$B$46)/1000*Assumptions!$B$42 -> 403.33333 | N12: =CHOOSE(Assumptions!$B$10,K12,L12,M12) -> 214.66667 | O12: =IF(D12>Assumptions!$B$52,Assumptions!$B$51,Assumptions!$B$50) -> 0 | P12: =Assumptions!$B$53 -> 200 | Q12: =N12+O12+P12 -> 414.66667 | R12: =J12-Q12 -> 2133.3333 | S12: =S11+R12 -> 10455.444 | U12: =IF($A12>=Assumptions!$B$14,MIN(Assumptions!$B$5,Assumptions!$B$5*($A12-Assumptions!$B$14+1)/Assumptions!$B$6),0) -> 3055.5556 | V12: =IF($A12>=Assumptions!$B$15,MIN(Assumptions!$B$5,Assumptions!$B$5*($A12-Assumptions!$B$15+1)/Assumptions!$B$6),0) -> 833.33333 | W12: =IF($A12>=Assumptions!$B$16,MIN(Assumptions!$B$5,Assumptions!$B$5*($A12-Assumptions!$B$16+1)/Assumptions!$B$6),0) -> 0 | X12: =IF($A12>=Assumptions!$B$17,MIN(Assumptions!$B$5,Assumptions!$B$5*($A12-Assumptions!$B$17+1)/Assumptions!$B$6),0) -> 0 | Y12: =IF($A12>=Assumptions!$B$14,Assumptions!$B$7*MIN(1,($A12-Assumptions!$B$14+1)/Assumptions!$B$8),0) -> 22.916667 | Z12: =IF($A12>=Assumptions!$B$15,Assumptions!$B$7*MIN(1,($A12-Assumptions!$B$15+1)/Assumptions!$B$8),0) -> 6.25 | AA12: =IF($A12>=Assumptions!$B$16,Assumptions!$B$7*MIN(1,($A12-Assumptions!$B$16+1)/Assumptions!$B$8),0) -> 0 | AB12: =IF($A12>=Assumptions!$B$17,Assumptions!$B$7*MIN(1,($A12-Assumptions!$B$17+1)/Assumptions!$B$8),0) -> 0 | AC12: =D12*Assumptions!$B$21 -> 31111.111 | AD12: =D12*Assumptions!$B$22 -> 19444.444 | AE12: =D12*Assumptions!$B$23 -> 11666.667 | AF12: =D12*Assumptions!$B$24 -> 7777.7778 | AG12: =D12*Assumptions!$B$25 -> 23333.333 | AH12: =IF(AND(R12>=0,R11<0),A12,0) -> 0 | AI12: =IF(AND(S12>=0,S11<0),A12,0) -> 0
A13: 12 | B13: May 2027 | C13: =SUMPRODUCT(--(Assumptions!$B$14:$B$17<=$A13)) -> 2 | D13: =SUM(U13:X13) -> 4444.4444 | E13: =SUM(Y13:AB13) -> 33.333333 | F13: =E13*Assumptions!$B$9 -> 1966.6667 | G13: =D13*Assumptions!$B$29*Assumptions!$B$30*Assumptions!$B$31 -> 480 | H13: =D13*Assumptions!$B$32*Assumptions!$B$33 -> 465.33333 | I13: =D13*Assumptions!$B$26*Assumptions!$B$34/1000*Assumptions!$B$11 -> 0 | J13: =SUM(F13:I13) -> 2912 | K13: =MAX(0,(AC13+AD13+AE13+AF13+AG13)-Assumptions!$B$47)/1000*Assumptions!$B$43 -> 61.333333 | L13: =MAX(0,AD13-Assumptions!$B$46)/1000*Assumptions!$B$39+MAX(0,AE13-Assumptions!$B$46)/1000*Assumptions!$B$40+MAX(0,(AC13+AF13+AG13)-Assumptions!$B$47)/1000*Assumptions!$B$43 -> 297.33333 | M13: =MAX(0,AC13-Assumptions!$B$46)/1000*Assumptions!$B$38+MAX(0,AD13-Assumptions!$B$46)/1000*Assumptions!$B$39+MAX(0,AE13-Assumptions!$B$46)/1000*Assumptions!$B$40+MAX(0,AF13-Assumptions!$B$46)/1000*Assumptions!$B$41+MAX(0,AG13-Assumptions!$B$46)/1000*Assumptions!$B$42 -> 526.66667 | N13: =CHOOSE(Assumptions!$B$10,K13,L13,M13) -> 297.33333 | O13: =IF(D13>Assumptions!$B$52,Assumptions!$B$51,Assumptions!$B$50) -> 0 | P13: =Assumptions!$B$53 -> 200 | Q13: =N13+O13+P13 -> 497.33333 | R13: =J13-Q13 -> 2414.6667 | S13: =S12+R13 -> 12870.111 | U13: =IF($A13>=Assumptions!$B$14,MIN(Assumptions!$B$5,Assumptions!$B$5*($A13-Assumptions!$B$14+1)/Assumptions!$B$6),0) -> 3333.3333 | V13: =IF($A13>=Assumptions!$B$15,MIN(Assumptions!$B$5,Assumptions!$B$5*($A13-Assumptions!$B$15+1)/Assumptions!$B$6),0) -> 1111.1111 | W13: =IF($A13>=Assumptions!$B$16,MIN(Assumptions!$B$5,Assumptions!$B$5*($A13-Assumptions!$B$16+1)/Assumptions!$B$6),0) -> 0 | X13: =IF($A13>=Assumptions!$B$17,MIN(Assumptions!$B$5,Assumptions!$B$5*($A13-Assumptions!$B$17+1)/Assumptions!$B$6),0) -> 0 | Y13: =IF($A13>=Assumptions!$B$14,Assumptions!$B$7*MIN(1,($A13-Assumptions!$B$14+1)/Assumptions!$B$8),0) -> 25 | Z13: =IF($A13>=Assumptions!$B$15,Assumptions!$B$7*MIN(1,($A13-Assumptions!$B$15+1)/Assumptions!$B$8),0) -> 8.3333333 | AA13: =IF($A13>=Assumptions!$B$16,Assumptions!$B$7*MIN(1,($A13-Assumptions!$B$16+1)/Assumptions!$B$8),0) -> 0 | AB13: =IF($A13>=Assumptions!$B$17,Assumptions!$B$7*MIN(1,($A13-Assumptions!$B$17+1)/Assumptions!$B$8),0) -> 0 | AC13: =D13*Assumptions!$B$21 -> 35555.556 | AD13: =D13*Assumptions!$B$22 -> 22222.222 | AE13: =D13*Assumptions!$B$23 -> 13333.333 | AF13: =D13*Assumptions!$B$24 -> 8888.8889 | AG13: =D13*Assumptions!$B$25 -> 26666.667 | AH13: =IF(AND(R13>=0,R12<0),A13,0) -> 0 | AI13: =IF(AND(S13>=0,S12<0),A13,0) -> 0
A14: 13 | B14: Jun 2027 | C14: =SUMPRODUCT(--(Assumptions!$B$14:$B$17<=$A14)) -> 2 | D14: =SUM(U14:X14) -> 5000 | E14: =SUM(Y14:AB14) -> 35.416667 | F14: =E14*Assumptions!$B$9 -> 2089.5833 | G14: =D14*Assumptions!$B$29*Assumptions!$B$30*Assumptions!$B$31 -> 540 | H14: =D14*Assumptions!$B$32*Assumptions!$B$33 -> 523.5 | I14: =D14*Assumptions!$B$26*Assumptions!$B$34/1000*Assumptions!$B$11 -> 0 | J14: =SUM(F14:I14) -> 3153.0833 | K14: =MAX(0,(AC14+AD14+AE14+AF14+AG14)-Assumptions!$B$47)/1000*Assumptions!$B$43 -> 72 | L14: =MAX(0,AD14-Assumptions!$B$46)/1000*Assumptions!$B$39+MAX(0,AE14-Assumptions!$B$46)/1000*Assumptions!$B$40+MAX(0,(AC14+AF14+AG14)-Assumptions!$B$47)/1000*Assumptions!$B$43 -> 380 | M14: =MAX(0,AC14-Assumptions!$B$46)/1000*Assumptions!$B$38+MAX(0,AD14-Assumptions!$B$46)/1000*Assumptions!$B$39+MAX(0,AE14-Assumptions!$B$46)/1000*Assumptions!$B$40+MAX(0,AF14-Assumptions!$B$46)/1000*Assumptions!$B$41+MAX(0,AG14-Assumptions!$B$46)/1000*Assumptions!$B$42 -> 650 | N14: =CHOOSE(Assumptions!$B$10,K14,L14,M14) -> 380 | O14: =IF(D14>Assumptions!$B$52,Assumptions!$B$51,Assumptions!$B$50) -> 0 | P14: =Assumptions!$B$53 -> 200 | Q14: =N14+O14+P14 -> 580 | R14: =J14-Q14 -> 2573.0833 | S14: =S13+R14 -> 15443.194 | U14: =IF($A14>=Assumptions!$B$14,MIN(Assumptions!$B$5,Assumptions!$B$5*($A14-Assumptions!$B$14+1)/Assumptions!$B$6),0) -> 3611.1111 | V14: =IF($A14>=Assumptions!$B$15,MIN(Assumptions!$B$5,Assumptions!$B$5*($A14-Assumptions!$B$15+1)/Assumptions!$B$6),0) -> 1388.8889 | W14: =IF($A14>=Assumptions!$B$16,MIN(Assumptions!$B$5,Assumptions!$B$5*($A14-Assumptions!$B$16+1)/Assumptions!$B$6),0) -> 0 | X14: =IF($A14>=Assumptions!$B$17,MIN(Assumptions!$B$5,Assumptions!$B$5*($A14-Assumptions!$B$17+1)/Assumptions!$B$6),0) -> 0 | Y14: =IF($A14>=Assumptions!$B$14,Assumptions!$B$7*MIN(1,($A14-Assumptions!$B$14+1)/Assumptions!$B$8),0) -> 25 | Z14: =IF($A14>=Assumptions!$B$15,Assumptions!$B$7*MIN(1,($A14-Assumptions!$B$15+1)/Assumptions!$B$8),0) -> 10.416667 | AA14: =IF($A14>=Assumptions!$B$16,Assumptions!$B$7*MIN(1,($A14-Assumptions!$B$16+1)/Assumptions!$B$8),0) -> 0 | AB14: =IF($A14>=Assumptions!$B$17,Assumptions!$B$7*MIN(1,($A14-Assumptions!$B$17+1)/Assumptions!$B$8),0) -> 0 | AC14: =D14*Assumptions!$B$21 -> 40000 | AD14: =D14*Assumptions!$B$22 -> 25000 | AE14: =D14*Assumptions!$B$23 -> 15000 | AF14: =D14*Assumptions!$B$24 -> 10000 | AG14: =D14*Assumptions!$B$25 -> 30000 | AH14: =IF(AND(R14>=0,R13<0),A14,0) -> 0 | AI14: =IF(AND(S14>=0,S13<0),A14,0) -> 0
... A37: 36 | B37: May 2029 | C37: =SUMPRODUCT(--(Assumptions!$B$14:$B$17<=$A37)) -> 4 | D37: =SUM(U37:X37) -> 17777.778 | E37: =SUM(Y37:AB37) -> 95.833333 | F37: =E37*Assumptions!$B$9 -> 5654.1667 | G37: =D37*Assumptions!$B$29*Assumptions!$B$30*Assumptions!$B$31 -> 1920 | H37: =D37*Assumptions!$B$32*Assumptions!$B$33 -> 1861.3333 | I37: =D37*Assumptions!$B$26*Assumptions!$B$34/1000*Assumptions!$B$11 -> 0 | J37: =SUM(F37:I37) -> 9435.5 | K37: =MAX(0,(AC37+AD37+AE37+AF37+AG37)-Assumptions!$B$47)/1000*Assumptions!$B$43 -> 317.33333 | L37: =MAX(0,AD37-Assumptions!$B$46)/1000*Assumptions!$B$39+MAX(0,AE37-Assumptions!$B$46)/1000*Assumptions!$B$40+MAX(0,(AC37+AF37+AG37)-Assumptions!$B$47)/1000*Assumptions!$B$43 -> 2281.3333 | M37: =MAX(0,AC37-Assumptions!$B$46)/1000*Assumptions!$B$38+MAX(0,AD37-Assumptions!$B$46)/1000*Assumptions!$B$39+MAX(0,AE37-Assumptions!$B$46)/1000*Assumptions!$B$40+MAX(0,AF37-Assumptions!$B$46)/1000*Assumptions!$B$41+MAX(0,AG37-Assumptions!$B$46)/1000*Assumptions!$B$42 -> 3614.4444 | N37: =CHOOSE(Assumptions!$B$10,K37,L37,M37) -> 2281.3333 | O37: =IF(D37>Assumptions!$B$52,Assumptions!$B$51,Assumptions!$B$50) -> 45 | P37: =Assumptions!$B$53 -> 200 | Q37: =N37+O37+P37 -> 2526.3333 | R37: =J37-Q37 -> 6909.1667 | S37: =S36+R37 -> 127767.86 | U37: =IF($A37>=Assumptions!$B$14,MIN(Assumptions!$B$5,Assumptions!$B$5*($A37-Assumptions!$B$14+1)/Assumptions!$B$6),0) -> 5000 | V37: =IF($A37>=Assumptions!$B$15,MIN(Assumptions!$B$5,Assumptions!$B$5*($A37-Assumptions!$B$15+1)/Assumptions!$B$6),0) -> 5000 | W37: =IF($A37>=Assumptions!$B$16,MIN(Assumptions!$B$5,Assumptions!$B$5*($A37-Assumptions!$B$16+1)/Assumptions!$B$6),0) -> 5000 | X37: =IF($A37>=Assumptions!$B$17,MIN(Assumptions!$B$5,Assumptions!$B$5*($A37-Assumptions!$B$17+1)/Assumptions!$B$6),0) -> 2777.7778 | Y37: =IF($A37>=Assumptions!$B$14,Assumptions!$B$7*MIN(1,($A37-Assumptions!$B$14+1)/Assumptions!$B$8),0) -> 25 | Z37: =IF($A37>=Assumptions!$B$15,Assumptions!$B$7*MIN(1,($A37-Assumptions!$B$15+1)/Assumptions!$B$8),0) -> 25 | AA37: =IF($A37>=Assumptions!$B$16,Assumptions!$B$7*MIN(1,($A37-Assumptions!$B$16+1)/Assumptions!$B$8),0) -> 25 | AB37: =IF($A37>=Assumptions!$B$17,Assumptions!$B$7*MIN(1,($A37-Assumptions!$B$17+1)/Assumptions!$B$8),0) -> 20.833333 | AC37: =D37*Assumptions!$B$21 -> 142222.22 | AD37: =D37*Assumptions!$B$22 -> 88888.889 | AE37: =D37*Assumptions!$B$23 -> 53333.333 | AF37: =D37*Assumptions!$B$24 -> 35555.556 | AG37: =D37*Assumptions!$B$25 -> 106666.67 | AH37: =IF(AND(R37>=0,R36<0),A37,0) -> 0 | AI37: =IF(AND(S37>=0,S36<0),A37,0) -> 0

Sheet API Comparison
A1: API Cost Comparison
A2: What each map provider strategy costs per month at a given user base.
A3: Reference MAU | B3: 10000
B6: HERE-only | C6: Hybrid (rec.) | D6: Full Google
A7: Monthly API cost | B7: =MAX(0,($B$3*Assumptions!$B$21+$B$3*Assumptions!$B$22+$B$3*Assumptions!$B$23+$B$3*Assumptions!$B$24+$B$3*Assumptions!$B$25)-Assumptions!$B$47)/1000*Assumptions!$B$43 -> 168 | C7: =MAX(0,$B$3*Assumptions!$B$22-Assumptions!$B$46)/1000*Assumptions!$B$39+MAX(0,$B$3*Assumptions!$B$23-Assumptions!$B$46)/1000*Assumptions!$B$40+MAX(0,($B$3*Assumptions!$B$21+$B$3*Assumptions!$B$24+$B$3*Assumptions!$B$25)-Assumptions!$B$47)/1000*Assumptions!$B$43 -> 1124 | D7: =MAX(0,$B$3*Assumptions!$B$21-Assumptions!$B$46)/1000*Assumptions!$B$38+MAX(0,$B$3*Assumptions!$B$22-Assumptions!$B$46)/1000*Assumptions!$B$39+MAX(0,$B$3*Assumptions!$B$23-Assumptions!$B$46)/1000*Assumptions!$B$40+MAX(0,$B$3*Assumptions!$B$24-Assumptions!$B$46)/1000*Assumptions!$B$41+MAX(0,$B$3*Assumptions!$B$25-Assumptions!$B$46)/1000*Assumptions!$B$42 -> 1810
A8: Annual API cost | B8: =B7*12 -> 2016 | C8: =C7*12 -> 13488 | D8: =D7*12 -> 21720
A9: Cost per 1,000 MAU / month | B9: =B7/$B$3*1000 -> 16.8 | C9: =C7/$B$3*1000 -> 112.4 | D9: =D7/$B$3*1000 -> 181
A10: Relative to HERE-only | B10: =B7/$B$7 -> 1 | C10: =C7/$B$7 -> 6.6904762 | D10: =D7/$B$7 -> 10.77381
A12: Call volume & pricing detail (at reference MAU)
A13: SKU | B13: Calls / month | C13: Google €/1k | D13: HERE €/1k
A14: Map load | B14: =$B$3*Assumptions!$B$21 -> 80000 | C14: =Assumptions!$B$38 -> 7 | D14: =Assumptions!$B$43 -> 0.8
A15: Place search | B15: =$B$3*Assumptions!$B$22 -> 50000 | C15: =Assumptions!$B$39 -> 17 | D15: =Assumptions!$B$43 -> 0.8
A16: Place details + photos | B16: =$B$3*Assumptions!$B$23 -> 30000 | C16: =Assumptions!$B$40 -> 17 | D16: =Assumptions!$B$43 -> 0.8
A17: Geocoding | B17: =$B$3*Assumptions!$B$24 -> 20000 | C17: =Assumptions!$B$41 -> 5 | D17: =Assumptions!$B$43 -> 0.8
A18: Routing | B18: =$B$3*Assumptions!$B$25 -> 60000 | C18: =Assumptions!$B$42 -> 5 | D18: =Assumptions!$B$43 -> 0.8
A20: Hybrid = Google for Place search + details/photos (fixes 'not found' and bad images), HERE for map tiles, geocoding and routing.

Sheet Summary
A1: Lark — 3-Year Summary
A2: Driven by the Assumptions sheet. Scenario for costs = P&L scenario input.
B4: Year 1 | C4: Year 2 | D4: Year 3
A5: Sponsored listings | B5: =SUM('Monthly Model'!$F$2:$F$13) -> 10816.667 | C5: =SUM('Monthly Model'!$F$14:$F$25) -> 35400 | D5: =SUM('Monthly Model'!$F$26:$F$37) -> 58631.25
A6: Affiliate | B6: =SUM('Monthly Model'!$G$2:$G$13) -> 2640 | C6: =SUM('Monthly Model'!$G$14:$G$25) -> 10650 | D6: =SUM('Monthly Model'!$G$26:$G$37) -> 19410
A7: Subscription | B7: =SUM('Monthly Model'!$H$2:$H$13) -> 2559.3333 | C7: =SUM('Monthly Model'!$H$14:$H$25) -> 10324.583 | D7: =SUM('Monthly Model'!$H$26:$H$37) -> 18816.917
A8: CPM ads | B8: =SUM('Monthly Model'!$I$2:$I$13) -> 0 | C8: =SUM('Monthly Model'!$I$14:$I$25) -> 0 | D8: =SUM('Monthly Model'!$I$26:$I$37) -> 0
A9: Total revenue | B9: =SUM('Monthly Model'!$J$2:$J$13) -> 16016 | C9: =SUM('Monthly Model'!$J$14:$J$25) -> 56374.583 | D9: =SUM('Monthly Model'!$J$26:$J$37) -> 96858.167
A11: API cost (selected) | B11: =SUM('Monthly Model'!$N$2:$N$13) -> 745.88889 | C11: =SUM('Monthly Model'!$N$14:$N$25) -> 10305.333 | D11: =SUM('Monthly Model'!$N$26:$N$37) -> 22374.667
A12: Infra | B12: =SUM('Monthly Model'!$O$2:$O$13) -> 0 | C12: =SUM('Monthly Model'!$O$14:$O$25) -> 315 | D12: =SUM('Monthly Model'!$O$26:$O$37) -> 540
A13: Opex | B13: =SUM('Monthly Model'!$P$2:$P$13) -> 2400 | C13: =SUM('Monthly Model'!$P$14:$P$25) -> 2400 | D13: =SUM('Monthly Model'!$P$26:$P$37) -> 2400
A14: Total cost | B14: =SUM('Monthly Model'!$Q$2:$Q$13) -> 3145.8889 | C14: =SUM('Monthly Model'!$Q$14:$Q$25) -> 13020.333 | D14: =SUM('Monthly Model'!$Q$26:$Q$37) -> 25314.667
A16: Net profit / (loss) | B16: =SUM('Monthly Model'!$R$2:$R$13) -> 12870.111 | C16: =SUM('Monthly Model'!$R$14:$R$25) -> 43354.25 | D16: =SUM('Monthly Model'!$R$26:$R$37) -> 71543.5
A18: MAU at year end | B18: ='Monthly Model'!$D$13 -> 4444.4444 | C18: ='Monthly Model'!$D$25 -> 11388.889 | D18: ='Monthly Model'!$D$37 -> 17777.778
A21: Key outcomes
A22: Cumulative break-even month | B22: =IF(MAX('Monthly Model'!$AI$2:$AI$37)=0,"Not within 36 mo",MAX('Monthly Model'!$AI$2:$AI$37)) -> 2
A23: Monthly run-rate revenue (M36 ×12) | B23: ='Monthly Model'!$J$37*12 -> 113226
A24: Monthly run-rate net (M36 ×12) | B24: ='Monthly Model'!$R$37*12 -> 82910
A25: Net margin at M36 | B25: =IF('Monthly Model'!$J$37=0,0,'Monthly Model'!$R$37/'Monthly Model'!$J$37) -> 0.73225231
